<?xml version="1.0" ?>
<sdf version='1.6'>
  <model name='barrett'>
    <link name='palm_link'>
      <kinematic>true</kinematic>
      <pose frame=''>0 0 0 0 -0 -3.14159</pose>
      <inertial>
        <pose frame=''>-5.1e-05 0.005043 0.036674 0 -0 0</pose>
        <mass>0.50575</mass>
        <inertia>
          <ixx>4.04627e-05</ixx>
          <ixy>-5.60348e-08</ixy>
          <ixz>-4.20341e-05</ixz>
          <iyy>0.000226138</iyy>
          <iyz>1.39217e-07</iyz>
          <izz>0.000202451</izz>
        </inertia>
      </inertial>
      <collision name='palm_link_collision'>
        <pose frame=''>0 0 0 0 -0 0</pose>
        <geometry>
          <mesh>
            <scale>1 1 1</scale>
            <uri>model://barrett/mesh/palm_convex.dae</uri>
          </mesh>
        </geometry>
        <surface>
          <contact>
            <ode>
              <kp>1000000</kp>
              <kd>100</kd>
            </ode>
          </contact>
          <friction>
            <ode>
              <mu>0.5</mu>
              <mu2>0.5</mu2>
            </ode>
          </friction>
        </surface>
      </collision>
      <visual name='palm_link_visual'>
        <pose frame=''>0 0 0 0 -0 0</pose>
        <geometry>
          <mesh>
            <scale>1 1 1</scale>
            <uri>model://barrett/mesh/palm_fine.stl</uri>
          </mesh>
        </geometry>
        <material>
          <ambient>0.3 0.3 0.3 1</ambient>
          <diffuse>0.1 0.5 0.9 1</diffuse>
          <specular>0.5 0.5 0.5 1</specular>
          <script>
            <uri>__default__</uri>
            <name>__default__</name>
          </script>
        </material>
      </visual>
      <gravity>0</gravity>
      <self_collide>0</self_collide>
    </link>
    <link name='finger_1_prox_link'>
      <pose frame=''>0.025 0 0.0415 0 -0 1.5708</pose>
      <inertial>
        <pose frame=''>0.023133 0.000786 0.000528 0 -0 0</pose>
        <mass>0.14109</mass>
        <inertia>
          <ixx>4.872e-06</ixx>
          <ixy>1.7103e-06</ixy>
          <ixz>3.4041e-08</ixz>
          <iyy>7.6588e-05</iyy>
          <iyz>2.3133e-08</iyz>
          <izz>7.7733e-05</izz>
        </inertia>
      </inertial>
      <collision name='finger_1_prox_link_collision'>
        <pose frame=''>0 0 0 0 -0 0</pose>
        <geometry>
          <mesh>
            <scale>1 1 1</scale>
            <uri>model://barrett/mesh/finger_prox_link_convex.dae</uri>
          </mesh>
        </geometry>
        <surface>
          <contact>
            <ode>
              <kp>1000000</kp>
              <kd>100</kd>
            </ode>
          </contact>
          <friction>
            <ode>
              <mu>0.5</mu>
              <mu2>0.5</mu2>
            </ode>
          </friction>
        </surface>
      </collision>
      <visual name='finger_1_prox_link_visual'>
        <pose frame=''>0 0 0 0 -0 0</pose>
        <geometry>
          <mesh>
            <scale>1 1 1</scale>
            <uri>model://barrett/mesh/finger_prox_link_fine.stl</uri>
          </mesh>
        </geometry>
        <material>
          <ambient>0.3 0.3 0.3 1</ambient>
          <diffuse>0.1 0.5 0.9 1</diffuse>
          <specular>0.5 0.5 0.5 1</specular>
          <script>
            <uri>__default__</uri>
            <name>__default__</name>
          </script>
        </material>
      </visual>
      <gravity>0</gravity>
      <self_collide>1</self_collide>
    </link>
    <joint name='finger_1_prox_joint' type='revolute'>
      <child>finger_1_prox_link</child>
      <parent>palm_link</parent>
      <axis>
        <xyz>0 0 -1</xyz>
        <limit>
          <lower>0</lower>
          <upper>3.14159</upper>
          <effort>5</effort>
          <velocity>10</velocity>
        </limit>
        <dynamics>
          <damping>0.35</damping>
          <friction>0</friction>
          <spring_reference>0</spring_reference>
          <spring_stiffness>0</spring_stiffness>
        </dynamics>
        <use_parent_model_frame>1</use_parent_model_frame>
      </axis>
      <physics>
        <ode>
          <provide_feedback>0</provide_feedback>
          <implicit_spring_damper>1</implicit_spring_damper>
          <cfm_damping>1</cfm_damping>
          <limit>
            <cfm>0</cfm>
            <erp>0.2</erp>
          </limit>
        </ode>
      </physics>
    </joint>
    <link name='finger_1_med_link'>
      <pose frame=''>0.025 0.05 0.0754 1.5708 -0 1.5708</pose>
      <inertial>
        <pose frame=''>0.023133 0.000786 0.000528 0 -0 0</pose>
        <mass>0.062139</mass>
        <inertia>
          <ixx>4.872e-06</ixx>
          <ixy>1.7103e-06</ixy>
          <ixz>3.4041e-08</ixz>
          <iyy>7.6588e-05</iyy>
          <iyz>2.3133e-08</iyz>
          <izz>7.7733e-05</izz>
        </inertia>
      </inertial>
      <collision name='finger_1_med_link_collision'>
        <pose frame=''>0 0 0 0 -0 0</pose>
        <geometry>
          <mesh>
            <scale>1 1 1</scale>
            <uri>model://barrett/mesh/finger_med_link_convex.dae</uri>
          </mesh>
        </geometry>
        <surface>
          <contact>
            <ode>
              <kp>1000000</kp>
              <kd>100</kd>
            </ode>
          </contact>
          <friction>
            <ode>
              <mu>0.5</mu>
              <mu2>0.5</mu2>
            </ode>
          </friction>
        </surface>
      </collision>
      <visual name='finger_1_med_link_visual'>
        <pose frame=''>0 0 0 0 -0 0</pose>
        <geometry>
          <mesh>
            <scale>1 1 1</scale>
            <uri>model://barrett/mesh/finger_med_link_fine.stl</uri>
          </mesh>
        </geometry>
        <material>
          <ambient>0.7 0.7 0.7 1</ambient>
          <diffuse>0.9 0.9 0.9 1</diffuse>
          <specular>0.5 0.5 0.5 0.3</specular>
          <emissive>0 0 0 0</emissive>
          <script>
            <uri>__default__</uri>
            <name>__default__</name>
          </script>
        </material>
      </visual>
      <gravity>0</gravity>
      <self_collide>1</self_collide>
    </link>
    <joint name='finger_1_med_joint' type='revolute'>
      <child>finger_1_med_link</child>
      <parent>finger_1_prox_link</parent>
      <axis>
        <xyz>1 0 0</xyz>
        <limit>
          <lower>0</lower>
          <upper>2.44346</upper>
          <effort>30</effort>
          <velocity>10</velocity>
        </limit>
        <dynamics>
          <damping>0.35</damping>
          <friction>0</friction>
          <spring_reference>0</spring_reference>
          <spring_stiffness>0</spring_stiffness>
        </dynamics>
        <use_parent_model_frame>1</use_parent_model_frame>
      </axis>
      <physics>
        <ode>
          <provide_feedback>0</provide_feedback>
          <implicit_spring_damper>1</implicit_spring_damper>
          <cfm_damping>1</cfm_damping>
          <limit>
            <cfm>0</cfm>
            <erp>0.2</erp>
          </limit>
        </ode>
      </physics>
    </joint>
    <link name='finger_1_dist_link'>
      <pose frame=''>0.025 0.11994 0.0784 1.5708 -0.785398 1.5708</pose>
      <inertial>
        <pose frame=''>0.022826 0.001049 0.00042 0 -0 0</pose>
        <mass>0.041378</mass>
        <inertia>
          <ixx>4.1582e-06</ixx>
          <ixy>1.43083e-06</ixy>
          <ixz>1.01071e-07</ixz>
          <iyy>3.93767e-05</iyy>
          <iyz>-4.40926e-13</iyz>
          <izz>3.82757e-05</izz>
        </inertia>
      </inertial>
      <collision name='finger_1_dist_link_collision'>
        <pose frame=''>0 0 0 0 0 -0.785398</pose>
        <geometry>
          <mesh>
            <scale>1 1 1</scale>
            <uri>model://barrett/mesh/finger_dist_link_convex.dae</uri>
          </mesh>
        </geometry>
        <surface>
          <contact>
            <ode>
              <kp>1000000</kp>
              <kd>100</kd>
            </ode>
          </contact>
          <friction>
            <ode>
              <mu>0.5</mu>
              <mu2>0.5</mu2>
            </ode>
          </friction>
        </surface>
      </collision>
      <visual name='finger_1_dist_link_visual'>
        <pose frame=''>0 0 0 0 0 -0.785398</pose>
        <geometry>
          <mesh>
            <scale>1 1 1</scale>
            <uri>model://barrett/mesh/finger_dist_link_fine.stl</uri>
          </mesh>
        </geometry>
        <material>
          <ambient>0.7 0.7 0.7 1</ambient>
          <diffuse>0.9 0.9 0.9 1</diffuse>
          <specular>0.5 0.5 0.5 0.3</specular>
          <emissive>0 0 0 0</emissive>
          <script>
            <uri>__default__</uri>
            <name>__default__</name>
          </script>
        </material>
      </visual>
      <gravity>0</gravity>
      <self_collide>1</self_collide>
    </link>
    <joint name='finger_1_dist_joint' type='revolute'>
      <child>finger_1_dist_link</child>
      <parent>finger_1_med_link</parent>
      <axis>
        <xyz>1 0 0</xyz>
        <limit>
          <lower>0</lower>
          <upper>0.837758</upper>
          <effort>30</effort>
          <velocity>10</velocity>
        </limit>
        <dynamics>
          <damping>0.35</damping>
          <friction>1</friction>
          <spring_reference>0</spring_reference>
          <spring_stiffness>0</spring_stiffness>
        </dynamics>
        <use_parent_model_frame>1</use_parent_model_frame>
      </axis>
      <physics>
        <ode>
          <provide_feedback>0</provide_feedback>
          <implicit_spring_damper>1</implicit_spring_damper>
          <cfm_damping>1</cfm_damping>
          <limit>
            <cfm>0</cfm>
            <erp>0.2</erp>
          </limit>
        </ode>
      </physics>
    </joint>
    <link name='finger_2_prox_link'>
      <pose frame=''>-0.025 -0 0.0415 0 -0 1.5708</pose>
      <inertial>
        <pose frame=''>0.023133 0.000786 0.000528 0 -0 0</pose>
        <mass>0.14109</mass>
        <inertia>
          <ixx>4.872e-06</ixx>
          <ixy>1.7103e-06</ixy>
          <ixz>3.4041e-08</ixz>
          <iyy>7.6588e-05</iyy>
          <iyz>2.3133e-08</iyz>
          <izz>7.7733e-05</izz>
        </inertia>
      </inertial>
      <collision name='finger_2_prox_link_collision'>
        <pose frame=''>0 0 0 0 -0 0</pose>
        <geometry>
          <mesh>
            <scale>1 1 1</scale>
            <uri>model://barrett/mesh/finger_prox_link_convex.dae</uri>
          </mesh>
        </geometry>
        <surface>
          <contact>
            <ode>
              <kp>1000000</kp>
              <kd>100</kd>
            </ode>
          </contact>
          <friction>
            <ode>
              <mu>0.5</mu>
              <mu2>0.5</mu2>
            </ode>
          </friction>
        </surface>
      </collision>
      <visual name='finger_2_prox_link_visual'>
        <pose frame=''>0 0 0 0 -0 0</pose>
        <geometry>
          <mesh>
            <scale>1 1 1</scale>
            <uri>model://barrett/mesh/finger_prox_link_fine.stl</uri>
          </mesh>
        </geometry>
        <material>
          <ambient>0.3 0.3 0.3 1</ambient>
          <diffuse>0.1 0.5 0.9 1</diffuse>
          <specular>0.5 0.5 0.5 1</specular>
          <script>
            <uri>__default__</uri>
            <name>__default__</name>
          </script>
        </material>
      </visual>
      <gravity>0</gravity>
      <self_collide>1</self_collide>
    </link>
    <joint name='finger_2_prox_joint' type='revolute'>
      <child>finger_2_prox_link</child>
      <parent>palm_link</parent>
      <axis>
        <xyz>0 0 1</xyz>
        <limit>
          <lower>0</lower>
          <upper>3.14159</upper>
          <effort>5</effort>
          <velocity>10</velocity>
        </limit>
        <dynamics>
          <damping>0.35</damping>
          <friction>0</friction>
          <spring_reference>0</spring_reference>
          <spring_stiffness>0</spring_stiffness>
        </dynamics>
        <use_parent_model_frame>1</use_parent_model_frame>
      </axis>
      <physics>
        <ode>
          <provide_feedback>0</provide_feedback>
          <implicit_spring_damper>1</implicit_spring_damper>
          <cfm_damping>1</cfm_damping>
          <limit>
            <cfm>0</cfm>
            <erp>0.2</erp>
          </limit>
        </ode>
      </physics>
    </joint>
    <link name='finger_2_med_link'>
      <pose frame=''>-0.025 0.05 0.0754 1.5708 -0 1.5708</pose>
      <inertial>
        <pose frame=''>0.023133 0.000786 0.000528 0 -0 0</pose>
        <mass>0.062139</mass>
        <inertia>
          <ixx>4.872e-06</ixx>
          <ixy>1.7103e-06</ixy>
          <ixz>3.4041e-08</ixz>
          <iyy>7.6588e-05</iyy>
          <iyz>2.3133e-08</iyz>
          <izz>7.7733e-05</izz>
        </inertia>
      </inertial>
      <collision name='finger_2_med_link_collision'>
        <pose frame=''>0 0 0 0 -0 0</pose>
        <geometry>
          <mesh>
            <scale>1 1 1</scale>
            <uri>model://barrett/mesh/finger_med_link_convex.dae</uri>
          </mesh>
        </geometry>
        <surface>
          <contact>
            <ode>
              <kp>1000000</kp>
              <kd>100</kd>
            </ode>
          </contact>
          <friction>
            <ode>
              <mu>0.5</mu>
              <mu2>0.5</mu2>
            </ode>
          </friction>
        </surface>
      </collision>
      <visual name='finger_2_med_link_visual'>
        <pose frame=''>0 0 0 0 -0 0</pose>
        <geometry>
          <mesh>
            <scale>1 1 1</scale>
            <uri>model://barrett/mesh/finger_med_link_fine.stl</uri>
          </mesh>
        </geometry>
        <material>
          <ambient>0.7 0.7 0.7 1</ambient>
          <diffuse>0.9 0.9 0.9 1</diffuse>
          <specular>0.5 0.5 0.5 0.3</specular>
          <emissive>0 0 0 0</emissive>
          <script>
            <uri>__default__</uri>
            <name>__default__</name>
          </script>
        </material>
      </visual>
      <gravity>0</gravity>
      <self_collide>1</self_collide>
    </link>
    <joint name='finger_2_med_joint' type='revolute'>
      <child>finger_2_med_link</child>
      <parent>finger_2_prox_link</parent>
      <axis>
        <xyz>1 0 0</xyz>
        <limit>
          <lower>0</lower>
          <upper>2.44346</upper>
          <effort>30</effort>
          <velocity>10</velocity>
        </limit>
        <dynamics>
          <damping>0.35</damping>
          <friction>0</friction>
          <spring_reference>0</spring_reference>
          <spring_stiffness>0</spring_stiffness>
        </dynamics>
        <use_parent_model_frame>1</use_parent_model_frame>
      </axis>
      <physics>
        <ode>
          <provide_feedback>0</provide_feedback>
          <implicit_spring_damper>1</implicit_spring_damper>
          <cfm_damping>1</cfm_damping>
          <limit>
            <cfm>0</cfm>
            <erp>0.2</erp>
          </limit>
        </ode>
      </physics>
    </joint>
    <link name='finger_2_dist_link'>
      <pose frame=''>-0.025 0.11994 0.0784 1.5708 -0.785398 1.5708</pose>
      <inertial>
        <pose frame=''>0.022826 0.001049 0.00042 0 -0 0</pose>
        <mass>0.041378</mass>
        <inertia>
          <ixx>4.1582e-06</ixx>
          <ixy>1.43083e-06</ixy>
          <ixz>1.01071e-07</ixz>
          <iyy>3.93767e-05</iyy>
          <iyz>-4.40926e-13</iyz>
          <izz>3.82757e-05</izz>
        </inertia>
      </inertial>
      <collision name='finger_2_dist_link_collision'>
        <pose frame=''>0 0 0 0 0 -0.785398</pose>
        <geometry>
          <mesh>
            <scale>1 1 1</scale>
            <uri>model://barrett/mesh/finger_dist_link_convex.dae</uri>
          </mesh>
        </geometry>
        <surface>
          <contact>
            <ode>
              <kp>1000000</kp>
              <kd>100</kd>
            </ode>
          </contact>
          <friction>
            <ode>
              <mu>0.5</mu>
              <mu2>0.5</mu2>
            </ode>
          </friction>
        </surface>
      </collision>
      <visual name='finger_2_dist_link_visual'>
        <pose frame=''>0 0 0 0 0 -0.785398</pose>
        <geometry>
          <mesh>
            <scale>1 1 1</scale>
            <uri>model://barrett/mesh/finger_dist_link_fine.stl</uri>
          </mesh>
        </geometry>
        <material>
          <ambient>0.7 0.7 0.7 1</ambient>
          <diffuse>0.9 0.9 0.9 1</diffuse>
          <specular>0.5 0.5 0.5 0.3</specular>
          <emissive>0 0 0 0</emissive>
          <script>
            <uri>__default__</uri>
            <name>__default__</name>
          </script>
        </material>
      </visual>
      <gravity>0</gravity>
      <self_collide>1</self_collide>
    </link>
    <joint name='finger_2_dist_joint' type='revolute'>
      <child>finger_2_dist_link</child>
      <parent>finger_2_med_link</parent>
      <axis>
        <xyz>1 0 0</xyz>
        <limit>
          <lower>0</lower>
          <upper>0.837758</upper>
          <effort>30</effort>
          <velocity>10</velocity>
        </limit>
        <dynamics>
          <damping>0.35</damping>
          <friction>1</friction>
          <spring_reference>0</spring_reference>
          <spring_stiffness>0</spring_stiffness>
        </dynamics>
        <use_parent_model_frame>1</use_parent_model_frame>
      </axis>
      <physics>
        <ode>
          <provide_feedback>0</provide_feedback>
          <implicit_spring_damper>1</implicit_spring_damper>
          <cfm_damping>1</cfm_damping>
          <limit>
            <cfm>0</cfm>
            <erp>0.2</erp>
          </limit>
        </ode>
      </physics>
    </joint>
    <link name='finger_3_med_link'>
      <pose frame=''>0 -0.05 0.0754 1.5708 -0 -1.5708</pose>
      <inertial>
        <pose frame=''>0.023133 0.000786 0.000528 0 -0 0</pose>
        <mass>0.062139</mass>
        <inertia>
          <ixx>4.872e-06</ixx>
          <ixy>1.7103e-06</ixy>
          <ixz>3.4041e-08</ixz>
          <iyy>7.6588e-05</iyy>
          <iyz>2.3133e-08</iyz>
          <izz>7.7733e-05</izz>
        </inertia>
      </inertial>
      <collision name='finger_3_med_link_collision'>
        <pose frame=''>0 0 0 0 -0 0</pose>
        <geometry>
          <mesh>
            <scale>1 1 1</scale>
            <uri>model://barrett/mesh/finger_med_link_convex.dae</uri>
          </mesh>
        </geometry>
        <surface>
          <contact>
            <ode>
              <kp>1000000</kp>
              <kd>100</kd>
            </ode>
          </contact>
          <friction>
            <ode>
              <mu>0.5</mu>
              <mu2>0.5</mu2>
            </ode>
          </friction>
        </surface>
      </collision>
      <visual name='finger_3_med_link_visual'>
        <pose frame=''>0 0 0 0 -0 0</pose>
        <geometry>
          <mesh>
            <scale>1 1 1</scale>
            <uri>model://barrett/mesh/finger_med_link_fine.stl</uri>
          </mesh>
        </geometry>
        <material>
          <ambient>0.7 0.7 0.7 1</ambient>
          <diffuse>0.9 0.9 0.9 1</diffuse>
          <specular>0.5 0.5 0.5 0.3</specular>
          <emissive>0 0 0 0</emissive>
          <script>
            <uri>__default__</uri>
            <name>__default__</name>
          </script>
        </material>
      </visual>
      <gravity>0</gravity>
      <self_collide>1</self_collide>
    </link>
    <joint name='finger_3_med_joint' type='revolute'>
      <child>finger_3_med_link</child>
      <parent>palm_link</parent>
      <axis>
        <xyz>-1 0 0</xyz>
        <limit>
          <lower>0</lower>
          <upper>2.44346</upper>
          <effort>30</effort>
          <velocity>10</velocity>
        </limit>
        <dynamics>
          <damping>0.35</damping>
          <friction>0</friction>
          <spring_reference>0</spring_reference>
          <spring_stiffness>0</spring_stiffness>
        </dynamics>
        <use_parent_model_frame>1</use_parent_model_frame>
      </axis>
      <physics>
        <ode>
          <provide_feedback>0</provide_feedback>
          <implicit_spring_damper>1</implicit_spring_damper>
          <cfm_damping>1</cfm_damping>
          <limit>
            <cfm>0</cfm>
            <erp>0.2</erp>
          </limit>
        </ode>
      </physics>
    </joint>
    <link name='finger_3_dist_link'>
      <pose frame=''>-0 -0.11994 0.0784 1.5708 -0.785398 -1.5708</pose>
      <inertial>
        <pose frame=''>0.022826 0.001049 0.00042 0 -0 0</pose>
        <mass>0.041378</mass>
        <inertia>
          <ixx>4.1582e-06</ixx>
          <ixy>1.43083e-06</ixy>
          <ixz>1.01071e-07</ixz>
          <iyy>3.93767e-05</iyy>
          <iyz>-4.40926e-13</iyz>
          <izz>3.82757e-05</izz>
        </inertia>
      </inertial>
      <collision name='finger_3_dist_link_collision'>
        <pose frame=''>0 0 0 0 0 -0.785398</pose>
        <geometry>
          <mesh>
            <scale>1 1 1</scale>
            <uri>model://barrett/mesh/finger_dist_link_convex.dae</uri>
          </mesh>
        </geometry>
        <surface>
          <contact>
            <ode>
              <kp>1000000</kp>
              <kd>100</kd>
            </ode>
          </contact>
          <friction>
            <ode>
              <mu>0.5</mu>
              <mu2>0.5</mu2>
            </ode>
          </friction>
        </surface>
      </collision>
      <visual name='finger_3_dist_link_visual'>
        <pose frame=''>0 0 0 0 0 -0.785398</pose>
        <geometry>
          <mesh>
            <scale>1 1 1</scale>
            <uri>model://barrett/mesh/finger_dist_link_fine.stl</uri>
          </mesh>
        </geometry>
        <material>
          <ambient>0.7 0.7 0.7 1</ambient>
          <diffuse>0.9 0.9 0.9 1</diffuse>
          <specular>0.5 0.5 0.5 0.3</specular>
          <emissive>0 0 0 0</emissive>
          <script>
            <uri>__default__</uri>
            <name>__default__</name>
          </script>
        </material>
      </visual>
      <gravity>0</gravity>
      <self_collide>1</self_collide>
    </link>
    <joint name='finger_3_dist_joint' type='revolute'>
      <child>finger_3_dist_link</child>
      <parent>finger_3_med_link</parent>
      <axis>
        <xyz>-1 0 0</xyz>
        <limit>
          <lower>0</lower>
          <upper>0.837758</upper>
          <effort>30</effort>
          <velocity>10</velocity>
        </limit>
        <dynamics>
          <damping>0.35</damping>
          <friction>1</friction>
          <spring_reference>0</spring_reference>
          <spring_stiffness>0</spring_stiffness>
        </dynamics>
        <use_parent_model_frame>1</use_parent_model_frame>
      </axis>
      <physics>
        <ode>
          <provide_feedback>0</provide_feedback>
          <implicit_spring_damper>1</implicit_spring_damper>
          <cfm_damping>1</cfm_damping>
          <limit>
            <cfm>0</cfm>
            <erp>0.2</erp>
          </limit>
        </ode>
      </physics>
    </joint>
    <static>0</static>
  </model>
</sdf>
